Traceback (most recent call last):
  File "/Users/julian/anaconda3/lib/python3.10/site-packages/jupyter_cache/executors/utils.py", line 58, in single_nb_execution
    executenb(
  File "/Users/julian/anaconda3/lib/python3.10/site-packages/nbclient/client.py", line 1204, in execute
    return NotebookClient(nb=nb, resources=resources, km=km, **kwargs).execute()
  File "/Users/julian/anaconda3/lib/python3.10/site-packages/nbclient/util.py", line 84, in wrapped
    return just_run(coro(*args, **kwargs))
  File "/Users/julian/anaconda3/lib/python3.10/site-packages/nbclient/util.py", line 62, in just_run
    return loop.run_until_complete(coro)
  File "/Users/julian/anaconda3/lib/python3.10/asyncio/base_events.py", line 649, in run_until_complete
    return future.result()
  File "/Users/julian/anaconda3/lib/python3.10/site-packages/nbclient/client.py", line 663, in async_execute
    await self.async_execute_cell(
  File "/Users/julian/anaconda3/lib/python3.10/site-packages/nbclient/client.py", line 965, in async_execute_cell
    await self._check_raise_for_error(cell, cell_index, exec_reply)
  File "/Users/julian/anaconda3/lib/python3.10/site-packages/nbclient/client.py", line 862, in _check_raise_for_error
    raise CellExecutionError.from_cell_and_msg(cell, exec_reply_content)
nbclient.exceptions.CellExecutionError: An error occurred while executing the following cell:
------------------
# Imports
import plotly.graph_objs as go
import plotly.express as px
import matplotlib.pyplot as plt
import matplotlib.colors as colors
import seaborn as sns
import matplotlib.patches as mpatches
import fiona
import numpy as np
import pandas as pd
import geopandas as gpd
import importnb
from matplotlib import colors
from ipywidgets import interact
from importnb import Notebook
with Notebook():
    import cleaned_data

df1 = cleaned_data.df1
df2 = cleaned_data.df2
df2_copy = cleaned_data.df2_copy
df3 = cleaned_data.df3
df4 = cleaned_data.df4
------------------

[0;31m---------------------------------------------------------------------------[0m
[0;31mModuleNotFoundError[0m                       Traceback (most recent call last)
Cell [0;32mIn [1], line 2[0m
[1;32m      1[0m [38;5;66;03m# Imports[39;00m
[0;32m----> 2[0m [38;5;28;01mimport[39;00m [38;5;21;01mplotly[39;00m[38;5;21;01m.[39;00m[38;5;21;01mgraph_objs[39;00m [38;5;28;01mas[39;00m [38;5;21;01mgo[39;00m
[1;32m      3[0m [38;5;28;01mimport[39;00m [38;5;21;01mplotly[39;00m[38;5;21;01m.[39;00m[38;5;21;01mexpress[39;00m [38;5;28;01mas[39;00m [38;5;21;01mpx[39;00m
[1;32m      4[0m [38;5;28;01mimport[39;00m [38;5;21;01mmatplotlib[39;00m[38;5;21;01m.[39;00m[38;5;21;01mpyplot[39;00m [38;5;28;01mas[39;00m [38;5;21;01mplt[39;00m

[0;31mModuleNotFoundError[0m: No module named 'plotly'
ModuleNotFoundError: No module named 'plotly'

